<?xml version="1.0"?>

<robot name = "motorXacro" xmlns:xacro="http://www.ros.org/wiki/xacro">
    
    <xacro:macro name = "motor" params = "name axis fixed_parent revolute_child *revolute_origin">

        <!-- Attach the child link through a revolute joint -->
        <joint name = "${name}_joint" type = "revolute">
            <parent link = "${fixed_parent}"/>
            <!-- <parent link = "${name}_motor"/> -->
            <child  link = "${revolute_child}"/>
            <xacro:insert_block name = "revolute_origin"/> <!-- transformation from parent origin to child origin -->
            <limit upper = "1e10" lower = "-1e10" effort = "1e6" velocity = "1e6"/>
            <xacro:insert_block name = "joint_friction"/>
            <axis xyz = "${axis}"/>
        </joint>

        <xacro:if value = "${full_urdf}">
        <!-- implicitSpringDamper: prevent crashing when damping is set -->
        <!-- provideFeedback     : allows the joint to publish torque data -->
        <gazebo reference = "${name}_joint">
            <physics>
                <ode>
                    <max_force>50</max_force>
                </ode>
            </physics>
            <provideFeedback>true</provideFeedback>
            <implicitSpringDamper>true</implicitSpringDamper>
        </gazebo>

        <gazebo reference = "${revolute_child}">
            <self_collide>false</self_collide>
        </gazebo>
        </xacro:if>

    </xacro:macro>

</robot>